Workbook

Sheet TOP3277
A1: 网站名称 | B1: URL
A2: 百度 | B2: baidu.com
A3: 知乎 | B3: zhihu.com
A4: 腾讯网 | B4: qq.com
A5: 搜狐 | B5: sohu.com
A6: 哔哩哔哩 | B6: bilibili.com
A7: 网易网 | B7: 163.com
A8: 好搜 | B8: so.com
A9: 微信公众平台 | B9: mp.weixin.qq.com
A10: 抖音短视频 | B10: douyin.com
A11: 阿里巴巴 | B11: 1688.com
A12: 新浪微博 | B12: weibo.com
... A411: 起名网 | B411: yw11.com
A412: 17173 | B412: 17173.com
A413: 腾牛网 | B413: qqtn.com
A414: 工具查 | B414: gjcha.com
A415: 雪球网 | B415: xueqiu.com
A416: 星座屋网站 | B416: xzw.com
A417: 顺企网 | B417: 11467.com
A418: 文档投稿赚钱 | B418: book118.com
A419: 卜易居免费算命 | B419: buyiju.com
A420: 中国广播网 | B420: cnr.cn
A421: 律师 | B421: 64365.com
A422: 豆丁 | B422: docin.com
A423: 猫眼电影 | B423: maoyan.com
A424: 海词网 | B424: dict.cn
... A2778: 小飞兔软件 | B2778: xftsoft.com

Sheet 原始数据
A1: 网站名称 | B1: URL | C1: 全网流量总和左 | D1: 全网流量总和右 | E1: 站长之家平均流量 | F1: 百度来路左 | G1: 百度来路右 | H1: 爱站平均流量
A2: 重庆分类目录网 | B2: 023dir.com | C2: 25363 | D2: 40515 | E2: =SUM(C2,D2)/2 -> 32939 | F2: 10118 | G2: 15038 | H2: =SUM(F2,G2)/2 -> 12578
A3: 大连海岛旅游网 | B3: 0411hd.com | C3: 11313 | D3: 18071 | E3: =SUM(C3,D3)/2 -> 14692 | F3: 5579 | G3: 7656 | H3: =SUM(F3,G3)/2 -> 6617.5
A4: 合肥顺驰电子科技 | B4: 0551soft.com | C4: 0 | D4: 0 | E4: =SUM(C4,D4)/2 -> 0 | F4: 0 | G4: 0 | H4: =SUM(F4,G4)/2 -> 0
A5: 厦门创易网 | B5: 0592ui.com | C5: 30 | D5: 48 | E5: =SUM(C5,D5)/2 -> 39 | F5: 46 | G5: 56 | H5: =SUM(F5,G5)/2 -> 51
A6: 零度软件园 | B6: 05sun.net | C6: 6 | D6: 10 | E6: =SUM(C6,D6)/2 -> 8 | F6: 7 | G6: 10 | H6: =SUM(F6,G6)/2 -> 8.5
A7: 珠宝网 | B7: 0755zb.com | C7: 23846 | D7: 38092 | E7: =SUM(C7,D7)/2 -> 30969 | F7: 6277 | G7: 9730 | H7: =SUM(F7,G7)/2 -> 8003.5
A8: 壮游奇迹MU特色专区 | B8: 1000uc.com | C8: 3635 | D8: 5809 | E8: =SUM(C8,D8)/2 -> 4722 | F8: 4182 | G8: 6084 | H8: =SUM(F8,G8)/2 -> 5133
A9: 千助北京网站建设公司 | B9: 1000zhu.com | C9: 75 | D9: 121 | E9: =SUM(C9,D9)/2 -> 98 | F9: 38 | G9: 55 | H9: =SUM(F9,G9)/2 -> 46.5
A10: 中国联通网上营业厅 | B10: 10010.com | C10: 83211 | D10: 132923 | E10: =SUM(C10,D10)/2 -> 108067 | F10: 22470 | G10: 31833 | H10: =SUM(F10,G10)/2 -> 27151.5
A11: 中国移动 | B11: 10086.cn | C11: 437548 | D11: 698940 | E11: =SUM(C11,D11)/2 -> 568244 | F11: 98968 | G11: 139226 | H11: =SUM(F11,G11)/2 -> 119097
A12: 百田网 | B12: 100bt.com | C12: 15928 | D12: 25444 | E12: =SUM(C12,D12)/2 -> 20686 | F12: 7025 | G12: 9186 | H12: =SUM(F12,G12)/2 -> 8105.5
A13: 生意社 | B13: 100ppi.com | C13: 41666 | D13: 66558 | E13: =SUM(C13,D13)/2 -> 54112 | F13: 4117 | G13: 6391 | H13: =SUM(F13,G13)/2 -> 5254
... A272: 雅昌艺术网 | B272: artron.net | C272: 24660 | D272: 39394 | E272: =SUM(C272,D272)/2 -> 32027 | F272: 8362 | G272: 12609 | H272: =SUM(F272,G272)/2 -> 10485.5
A273: 百度应用 | B273: as.baidu.com | E273: =SUM(C273,D273)/2 -> 0 | F273: 33723 | G273: 110439 | H273: =SUM(F273,G273)/2 -> 72081
A274: 爱思资源网 | B274: aseoe.com | C274: 23 | D274: 37 | E274: =SUM(C274,D274)/2 -> 30 | F274: 14 | G274: 22 | H274: =SUM(F274,G274)/2 -> 18
A275: 阜宁县安顺房屋平移 | B275: asfwpy.com | C275: 63 | D275: 99 | E275: =SUM(C275,D275)/2 -> 81 | F275: 8 | G275: 12 | H275: =SUM(F275,G275)/2 -> 10
A276: 39问医生 | B276: ask.39.net | C276: 51738 | D276: 82644 | E276: =SUM(C276,D276)/2 -> 67191 | F276: 37190 | G276: 45476 | H276: =SUM(F276,G276)/2 -> 41333
A277: 家庭医生 | B277: ask.familydoctor.com.cn | C277: 11589 | D277: 18515 | E277: =SUM(C277,D277)/2 -> 15052 | F277: 6323 | G277: 8946 | H277: =SUM(F277,G277)/2 -> 7634.5
A278: 问答 | B278: ask.zol.com.cn | C278: 41835 | D278: 66827 | E278: =SUM(C278,D278)/2 -> 54331 | F278: 76549 | G278: 115036 | H278: =SUM(F278,G278)/2 -> 95792.5
A279: 中商情报 | B279: askci.com | C279: 21206 | D279: 33877 | E279: =SUM(C279,D279)/2 -> 27541.5 | F279: 5072 | G279: 7933 | H279: =SUM(F279,G279)/2 -> 6502.5
A280: 易云同步分享盘 我的资料存储小站 | B280: asytech.cn | C280: 101 | D280: 161 | E280: =SUM(C280,D280)/2 -> 131 | F280: 4 | G280: 7 | H280: =SUM(F280,G280)/2 -> 5.5
A281: 安拓盈智能科技 | B281: atyzn.com | C281: 1 | D281: 1 | E281: =SUM(C281,D281)/2 -> 1 | F281: 1 | G281: 1 | H281: =SUM(F281,G281)/2 -> 1
A282: 澳柯玛电动车 | B282: aucma-ev.com | C282: 28582 | D282: 45656 | E282: =SUM(C282,D282)/2 -> 37119 | F282: 5145 | G282: 7876 | H282: =SUM(F282,G282)/2 -> 6510.5
A283: 一汽-大众奥迪 | B283: audi.cn | C283: 106111 | D283: 169502 | E283: =SUM(C283,D283)/2 -> 137806.5 | F283: 12669 | G283: 19411 | H283: =SUM(F283,G283)/2 -> 16040
A284: 杭州奥格工业设计 | B284: augid.cn | C284: 2 | D284: 2 | E284: =SUM(C284,D284)/2 -> 2 | F284: 2 | G284: 3 | H284: =SUM(F284,G284)/2 -> 2.5
A285: 上海昊量光电设备 | B285: auniontech.com | C285: 271 | D285: 431 | E285: =SUM(C285,D285)/2 -> 351 | F285: 36 | G285: 57 | H285: =SUM(F285,G285)/2 -> 46.5
... A295: 顺企网公司 | B295: b2b.11467.com | C295: 6649 | D295: 10623 | E295: =SUM(C295,D295)/2 -> 8636 | F295: 3851 | G295: 5993 | H295: =SUM(F295,G295)/2 -> 4922
A296: 爱采购 | B296: b2b.baidu.com | E296: =SUM(C296,D296)/2 -> 0 | F296: 2419100 | G296: 3368074 | H296: =SUM(F296,G296)/2 -> 2893587
A297: 中国B2B交易平台 | B297: b2b.biz | C297: 5431 | D297: 8677 | E297: =SUM(C297,D297)/2 -> 7054 | F297: 5565 | G297: 8336 | H297: =SUM(F297,G297)/2 -> 6950.5
A298: 黄页88公司名录网 | B298: b2b.huangye88.com | C298: 20002 | D298: 31952 | E298: =SUM(C298,D298)/2 -> 25977 | F298: 20195 | G298: 25671 | H298: =SUM(F298,G298)/2 -> 22933
A299: 拔草哦 | B299: bacaoo.com | C299: 25432 | D299: 40626 | E299: =SUM(C299,D299)/2 -> 33029 | F299: 10470 | G299: 16949 | H299: =SUM(F299,G299)/2 -> 13709.5
A300: 八卦帝 | B300: baguadi.com | C300: 2642 | D300: 4222 | E300: =SUM(C300,D300)/2 -> 3432 | F300: 5446 | G300: 8870 | H300: =SUM(F300,G300)/2 -> 7158
A301: 百度 | B301: baidu.com | E301: =SUM(C301,D301)/2 -> 0 | F301: 119665456 | G301: 177051487 | H301: =SUM(F301,G301)/2 -> 1.4835847e+08
A302: 中国天气站 | B302: baidu.weather.com.cn | C302: 869983 | D302: 1389715 | E302: =SUM(C302,D302)/2 -> 1129849 | F302: 34054 | G302: 74508 | H302: =SUM(F302,G302)/2 -> 54281
A303: 百和软件官网 | B303: baihesoft.com | C303: 9 | D303: 15 | E303: =SUM(C303,D303)/2 -> 12 | F303: 3 | G303: 4 | H303: =SUM(F303,G303)/2 -> 3.5
A304: 百家号 | B304: baijiahao.baidu.com | E304: =SUM(C304,D304)/2 -> 0 | F304: 28563706 | G304: 40516775 | H304: =SUM(F304,G304)/2 -> 34540240
A305: 百度百科 | B305: baike.baidu.com | E305: =SUM(C305,D305)/2 -> 0 | F305: 27483221 | G305: 32825411 | H305: =SUM(F305,G305)/2 -> 30154316
A306: 会计百科 | B306: baike.kuaiji.com | C306: 83063 | D306: 132685 | E306: =SUM(C306,D306)/2 -> 107874 | F306: 3682 | G306: 9620 | H306: =SUM(F306,G306)/2 -> 6651
A307: 太平洋汽车网汽车百科 | B307: baike.pcauto.com.cn | C307: 75378 | D307: 120410 | E307: =SUM(C307,D307)/2 -> 97894 | F307: 28853 | G307: 38513 | H307: =SUM(F307,G307)/2 -> 33683
...

Sheet 开发者600
A1: 网站名称 | B1: URL | C1: 综合流量 | D1: 开发者600排名
A2: 百度 | B2: baidu.com | C2: 296716943 | D2: 1
A3: 知乎 | B3: zhihu.com | C3: 16451772 | D3: 2
A4: 腾讯网 | B4: qq.com | C4: 12655436 | D4: 3
A5: 哔哩哔哩弹幕视频网 | B5: bilibili.com | C5: 10739342 | D5: 4
A6: 搜狐 | B6: sohu.com | C6: 10530398 | D6: 5
A7: 百度贴吧 | B7: tieba.baidu.com | C7: 10193446 | D7: 6
A8: 网易网 | B8: 163.com | C8: 7681633.9 | D8: 7
A9: 好搜 | B9: so.com | C9: 6986574.3 | D9: 8
A10: 百度图片 | B10: image.baidu.com | C10: 6395387 | D10: 9
A11: 百度文库 | B11: wenku.baidu.com | C11: 5057968 | D11: 10
A12: 微博 | B12: weibo.com | C12: 3386782.2 | D12: 11
A13: 百度地图 | B13: map.baidu.com | C13: 3018368 | D13: 12
... A599: 百度云OS | B599: os.baidu.com | C599: 0 | D599: 598

Sheet 开发者600原始
B1: 网站名称 | C1: URL | D1: 全网流量左 | E1: 全网流量右 | F1: 站长之家平均流量 | G1: 百度来路左 | H1: 百度来路右 | I1: 爱站平均流量 | J1: 综合流量 | K1: 开发者600排名 | L1: 综合排名
A2: 255 | B2: 百度 | C2: baidu.com | D2: {=INDEX('原始数据'!C$2:C$3689,MATCH($C2,'原始数据'!$B$2:$B$3689,0))} -> 0 | E2: {=INDEX('原始数据'!D$2:D$3689,MATCH($C2,'原始数据'!$B$2:$B$3689,0))} -> 0 | F2: {=INDEX('原始数据'!E$2:E$3689,MATCH($C2,'原始数据'!$B$2:$B$3689,0))} -> 0 | G2: {=INDEX('原始数据'!F$2:F$3689,MATCH($C2,'原始数据'!$B$2:$B$3689,0))} -> 119665456 | H2: {=INDEX('原始数据'!G$2:G$3689,MATCH($C2,'原始数据'!$B$2:$B$3689,0))} -> 177051487 | I2: {=INDEX('原始数据'!H$2:H$3689,MATCH($C2,'原始数据'!$B$2:$B$3689,0))} -> 1.4835847e+08 | J2: =IF(F2=0,I2*2,F2/$N$603+I2) -> 296716943 | K2: =ROW(K2)-1 -> 1 | L2: {=INDEX(TOP3277!#REF!,MATCH(C2,TOP3277!$B$501:$B$3035,0))} -> 1
A3: 331 | B3: 百度百科 | C3: baike.baidu.com | D3: {=INDEX('原始数据'!C$2:C$3689,MATCH($C3,'原始数据'!$B$2:$B$3689,0))} -> 0 | E3: {=INDEX('原始数据'!D$2:D$3689,MATCH($C3,'原始数据'!$B$2:$B$3689,0))} -> 0 | F3: {=INDEX('原始数据'!E$2:E$3689,MATCH($C3,'原始数据'!$B$2:$B$3689,0))} -> 0 | G3: {=INDEX('原始数据'!F$2:F$3689,MATCH($C3,'原始数据'!$B$2:$B$3689,0))} -> 27483221 | H3: {=INDEX('原始数据'!G$2:G$3689,MATCH($C3,'原始数据'!$B$2:$B$3689,0))} -> 32825411 | I3: {=INDEX('原始数据'!H$2:H$3689,MATCH($C3,'原始数据'!$B$2:$B$3689,0))} -> 30154316 | J3: =IF(F3=0,I3*2,F3/$N$603+I3) -> 60308632 | K3: =ROW(K3)-1 -> 2 | L3: {=INDEX(TOP3277!#REF!,MATCH(C3,TOP3277!$B$501:$B$3035,0))} -> 2
A4: 335 | B4: 百度知道 | C4: zhidao.baidu.com | F4: =SUM(D4+E4)/2 -> 0 | G4: 10027430 | H4: 15150163 | I4: =SUM(G4+H4)/2 -> 12588796 | J4: =IF(F4=0,I4*2,F4/$N$603+I4) -> 25177593 | K4: =ROW(K4)-1 -> 3 | L4: {=INDEX(TOP3277!#REF!,MATCH(C4,TOP3277!$B$501:$B$3035,0))} -> #N/A
A5: 268 | B5: 百度翻译 | C5: fanyi.baidu.com | F5: =SUM(D5+E5)/2 -> 0 | G5: 11178249 | H5: 12547041 | I5: =SUM(G5+H5)/2 -> 11862645 | J5: =IF(F5=0,I5*2,F5/$N$603+I5) -> 23725290 | K5: =ROW(K5)-1 -> 4 | L5: {=INDEX(TOP3277!#REF!,MATCH(C5,TOP3277!$B$501:$B$3035,0))} -> #N/A
A6: 264 | B6: 知乎 | C6: zhihu.com | D6: {=INDEX('原始数据'!C$2:C$3689,MATCH($C6,'原始数据'!$B$2:$B$3689,0))} -> 48517487 | E6: {=INDEX('原始数据'!D$2:D$3689,MATCH($C6,'原始数据'!$B$2:$B$3689,0))} -> 77501959 | F6: {=INDEX('原始数据'!E$2:E$3689,MATCH($C6,'原始数据'!$B$2:$B$3689,0))} -> 63009723 | G6: {=INDEX('原始数据'!F$2:F$3689,MATCH($C6,'原始数据'!$B$2:$B$3689,0))} -> 4251443 | H6: {=INDEX('原始数据'!G$2:G$3689,MATCH($C6,'原始数据'!$B$2:$B$3689,0))} -> 6013991 | I6: {=INDEX('原始数据'!H$2:H$3689,MATCH($C6,'原始数据'!$B$2:$B$3689,0))} -> 5132717 | J6: =IF(F6=0,I6*2,F6/$N$603+I6) -> 16451772 | K6: =ROW(K6)-1 -> 5 | L6: {=INDEX(TOP3277!#REF!,MATCH(C6,TOP3277!$B$501:$B$3035,0))} -> 4
A7: 256 | B7: 腾讯网 | C7: qq.com | D7: {=INDEX('原始数据'!C$2:C$3689,MATCH($C7,'原始数据'!$B$2:$B$3689,0))} -> 24644366 | E7: {=INDEX('原始数据'!D$2:D$3689,MATCH($C7,'原始数据'!$B$2:$B$3689,0))} -> 39366974 | F7: {=INDEX('原始数据'!E$2:E$3689,MATCH($C7,'原始数据'!$B$2:$B$3689,0))} -> 32005670 | G7: {=INDEX('原始数据'!F$2:F$3689,MATCH($C7,'原始数据'!$B$2:$B$3689,0))} -> 5875170 | H7: {=INDEX('原始数据'!G$2:G$3689,MATCH($C7,'原始数据'!$B$2:$B$3689,0))} -> 7936716 | I7: {=INDEX('原始数据'!H$2:H$3689,MATCH($C7,'原始数据'!$B$2:$B$3689,0))} -> 6905943 | J7: =IF(F7=0,I7*2,F7/$N$603+I7) -> 12655436 | K7: =ROW(K7)-1 -> 6 | L7: {=INDEX(TOP3277!#REF!,MATCH(C7,TOP3277!$B$501:$B$3035,0))} -> 5
A8: 261 | B8: 哔哩哔哩弹幕视频网 | C8: bilibili.com | D8: 12367232 | E8: 19755448 | F8: =SUM(D8+E8)/2 -> 16061340 | G8: 6536051 | H8: 9172120 | I8: =SUM(G8+H8)/2 -> 7854085.5 | J8: =IF(F8=0,I8*2,F8/$N$603+I8) -> 10739342 | K8: =ROW(K8)-1 -> 7 | L8: {=INDEX(TOP3277!#REF!,MATCH(C8,TOP3277!$B$501:$B$3035,0))} -> 8
A9: 257 | B9: 搜狐 | C9: sohu.com | D9: {=INDEX('原始数据'!C$2:C$3689,MATCH($C9,'原始数据'!$B$2:$B$3689,0))} -> 20313897 | E9: {=INDEX('原始数据'!D$2:D$3689,MATCH($C9,'原始数据'!$B$2:$B$3689,0))} -> 32449471 | F9: {=INDEX('原始数据'!E$2:E$3689,MATCH($C9,'原始数据'!$B$2:$B$3689,0))} -> 26381684 | G9: {=INDEX('原始数据'!F$2:F$3689,MATCH($C9,'原始数据'!$B$2:$B$3689,0))} -> 5056295 | H9: {=INDEX('原始数据'!G$2:G$3689,MATCH($C9,'原始数据'!$B$2:$B$3689,0))} -> 6526100 | I9: {=INDEX('原始数据'!H$2:H$3689,MATCH($C9,'原始数据'!$B$2:$B$3689,0))} -> 5791197.5 | J9: =IF(F9=0,I9*2,F9/$N$603+I9) -> 10530398 | K9: =ROW(K9)-1 -> 8 | L9: {=INDEX(TOP3277!#REF!,MATCH(C9,TOP3277!$B$501:$B$3035,0))} -> 6
A10: 330 | B10: 百度贴吧 | C10: tieba.baidu.com | D10: {=INDEX('原始数据'!C$2:C$3689,MATCH($C10,'原始数据'!$B$2:$B$3689,0))} -> 0 | E10: {=INDEX('原始数据'!D$2:D$3689,MATCH($C10,'原始数据'!$B$2:$B$3689,0))} -> 0 | F10: {=INDEX('原始数据'!E$2:E$3689,MATCH($C10,'原始数据'!$B$2:$B$3689,0))} -> 0 | G10: {=INDEX('原始数据'!F$2:F$3689,MATCH($C10,'原始数据'!$B$2:$B$3689,0))} -> 4305895 | H10: {=INDEX('原始数据'!G$2:G$3689,MATCH($C10,'原始数据'!$B$2:$B$3689,0))} -> 5887551 | I10: {=INDEX('原始数据'!H$2:H$3689,MATCH($C10,'原始数据'!$B$2:$B$3689,0))} -> 5096723 | J10: =IF(F10=0,I10*2,F10/$N$603+I10) -> 10193446 | K10: =ROW(K10)-1 -> 9 | L10: {=INDEX(TOP3277!#REF!,MATCH(C10,TOP3277!$B$501:$B$3035,0))} -> 7
A11: 13 | B11: 网易网 | C11: 163.com | D11: {=INDEX('原始数据'!C$2:C$3689,MATCH($C11,'原始数据'!$B$2:$B$3689,0))} -> 10588890 | E11: {=INDEX('原始数据'!D$2:D$3689,MATCH($C11,'原始数据'!$B$2:$B$3689,0))} -> 16914722 | F11: {=INDEX('原始数据'!E$2:E$3689,MATCH($C11,'原始数据'!$B$2:$B$3689,0))} -> 13751806 | G11: {=INDEX('原始数据'!F$2:F$3689,MATCH($C11,'原始数据'!$B$2:$B$3689,0))} -> 3513687 | H11: {=INDEX('原始数据'!G$2:G$3689,MATCH($C11,'原始数据'!$B$2:$B$3689,0))} -> 6908837 | I11: {=INDEX('原始数据'!H$2:H$3689,MATCH($C11,'原始数据'!$B$2:$B$3689,0))} -> 5211262 | J11: =IF(F11=0,I11*2,F11/$N$603+I11) -> 7681633.9 | K11: =ROW(K11)-1 -> 10 | L11: {=INDEX(TOP3277!#REF!,MATCH(C11,TOP3277!$B$501:$B$3035,0))} -> 9
A12: 259 | B12: 好搜 | C12: so.com | D12: {=INDEX('原始数据'!C$2:C$3689,MATCH($C12,'原始数据'!$B$2:$B$3689,0))} -> 25568836 | E12: {=INDEX('原始数据'!D$2:D$3689,MATCH($C12,'原始数据'!$B$2:$B$3689,0))} -> 40843726 | F12: {=INDEX('原始数据'!E$2:E$3689,MATCH($C12,'原始数据'!$B$2:$B$3689,0))} -> 33206281 | G12: {=INDEX('原始数据'!F$2:F$3689,MATCH($C12,'原始数据'!$B$2:$B$3689,0))} -> 759504 | H12: {=INDEX('原始数据'!G$2:G$3689,MATCH($C12,'原始数据'!$B$2:$B$3689,0))} -> 1283304 | I12: {=INDEX('原始数据'!H$2:H$3689,MATCH($C12,'原始数据'!$B$2:$B$3689,0))} -> 1021404 | J12: =IF(F12=0,I12*2,F12/$N$603+I12) -> 6986574.3 | K12: =ROW(K12)-1 -> 11 | L12: {=INDEX(TOP3277!#REF!,MATCH(C12,TOP3277!$B$501:$B$3035,0))} -> 10
A13: 332 | B13: 百度图片 | C13: image.baidu.com | F13: =SUM(D13+E13)/2 -> 0 | G13: 2795541 | H13: 3599846 | I13: =SUM(G13+H13)/2 -> 3197693.5 | J13: =IF(F13=0,I13*2,F13/$N$603+I13) -> 6395387 | K13: =ROW(K13)-1 -> 12 | L13: {=INDEX(TOP3277!#REF!,MATCH(C13,TOP3277!$B$501:$B$3035,0))} -> #N/A
A14: 333 | B14: 百度文库 | C14: wenku.baidu.com | D14: {=INDEX('原始数据'!C$2:C$3689,MATCH($C14,'原始数据'!$B$2:$B$3689,0))} -> 0 | E14: {=INDEX('原始数据'!D$2:D$3689,MATCH($C14,'原始数据'!$B$2:$B$3689,0))} -> 0 | F14: {=INDEX('原始数据'!E$2:E$3689,MATCH($C14,'原始数据'!$B$2:$B$3689,0))} -> 0 | G14: {=INDEX('原始数据'!F$2:F$3689,MATCH($C14,'原始数据'!$B$2:$B$3689,0))} -> 2226174 | H14: {=INDEX('原始数据'!G$2:G$3689,MATCH($C14,'原始数据'!$B$2:$B$3689,0))} -> 2831794 | I14: {=INDEX('原始数据'!H$2:H$3689,MATCH($C14,'原始数据'!$B$2:$B$3689,0))} -> 2528984 | J14: =IF(F14=0,I14*2,F14/$N$603+I14) -> 5057968 | K14: =ROW(K14)-1 -> 13 | L14: {=INDEX(TOP3277!#REF!,MATCH(C14,TOP3277!$B$501:$B$3035,0))} -> 14
A15: 201 | B15: 微博 | C15: weibo.com | D15: {=INDEX('原始数据'!C$2:C$3689,MATCH($C15,'原始数据'!$B$2:$B$3689,0))} -> 5615978 | E15: {=INDEX('原始数据'!D$2:D$3689,MATCH($C15,'原始数据'!$B$2:$B$3689,0))} -> 8970979 | F15: {=INDEX('原始数据'!E$2:E$3689,MATCH($C15,'原始数据'!$B$2:$B$3689,0))} -> 7293478.5 | G15: {=INDEX('原始数据'!F$2:F$3689,MATCH($C15,'原始数据'!$B$2:$B$3689,0))} -> 1664072 | H15: {=INDEX('原始数据'!G$2:G$3689,MATCH($C15,'原始数据'!$B$2:$B$3689,0))} -> 2489094 | I15: {=INDEX('原始数据'!H$2:H$3689,MATCH($C15,'原始数据'!$B$2:$B$3689,0))} -> 2076583 | J15: =IF(F15=0,I15*2,F15/$N$603+I15) -> 3386782.2 | K15: =ROW(K15)-1 -> 14 | L15: {=INDEX(TOP3277!#REF!,MATCH(C15,TOP3277!$B$501:$B$3035,0))} -> 17
A16: 338 | B16: 百度地图 | C16: map.baidu.com | F16: =SUM(D16+E16)/2 -> 0 | G16: 1365205 | H16: 1653163 | I16: =SUM(G16+H16)/2 -> 1509184 | J16: =IF(F16=0,I16*2,F16/$N$603+I16) -> 3018368 | K16: =ROW(K16)-1 -> 15 | L16: {=INDEX(TOP3277!#REF!,MATCH(C16,TOP3277!$B$501:$B$3035,0))} -> #N/A
A17: 258 | B17: 新浪网 | C17: sina.com.cn | D17: {=INDEX('原始数据'!C$2:C$3689,MATCH($C17,'原始数据'!$B$2:$B$3689,0))} -> 5237766 | E17: {=INDEX('原始数据'!D$2:D$3689,MATCH($C17,'原始数据'!$B$2:$B$3689,0))} -> 8366818 | F17: {=INDEX('原始数据'!E$2:E$3689,MATCH($C17,'原始数据'!$B$2:$B$3689,0))} -> 6802292 | G17: {=INDEX('原始数据'!F$2:F$3689,MATCH($C17,'原始数据'!$B$2:$B$3689,0))} -> 1354640 | H17: {=INDEX('原始数据'!G$2:G$3689,MATCH($C17,'原始数据'!$B$2:$B$3689,0))} -> 1895503 | I17: {=INDEX('原始数据'!H$2:H$3689,MATCH($C17,'原始数据'!$B$2:$B$3689,0))} -> 1625071.5 | J17: =IF(F17=0,I17*2,F17/$N$603+I17) -> 2847034 | K17: =ROW(K17)-1 -> 16 | L17: {=INDEX(TOP3277!#REF!,MATCH(C17,TOP3277!$B$501:$B$3035,0))} -> 21
A18: 260 | B18: 搜狗 | C18: sogou.com | D18: {=INDEX('原始数据'!C$2:C$3689,MATCH($C18,'原始数据'!$B$2:$B$3689,0))} -> 10447085 | E18: {=INDEX('原始数据'!D$2:D$3689,MATCH($C18,'原始数据'!$B$2:$B$3689,0))} -> 16688201 | F18: {=INDEX('原始数据'!E$2:E$3689,MATCH($C18,'原始数据'!$B$2:$B$3689,0))} -> 13567643 | G18: {=INDEX('原始数据'!F$2:F$3689,MATCH($C18,'原始数据'!$B$2:$B$3689,0))} -> 223668 | H18: {=INDEX('原始数据'!G$2:G$3689,MATCH($C18,'原始数据'!$B$2:$B$3689,0))} -> 318745 | I18: {=INDEX('原始数据'!H$2:H$3689,MATCH($C18,'原始数据'!$B$2:$B$3689,0))} -> 271206.5 | J18: =IF(F18=0,I18*2,F18/$N$603+I18) -> 2708495.4 | K18: =ROW(K18)-1 -> 17 | L18: {=INDEX(TOP3277!#REF!,MATCH(C18,TOP3277!$B$501:$B$3035,0))} -> 19
A19: 267 | B19: 优酷网 | C19: youku.com | D19: {=INDEX('原始数据'!C$2:C$3689,MATCH($C19,'原始数据'!$B$2:$B$3689,0))} -> 3712087 | E19: {=INDEX('原始数据'!D$2:D$3689,MATCH($C19,'原始数据'!$B$2:$B$3689,0))} -> 5929697 | F19: {=INDEX('原始数据'!E$2:E$3689,MATCH($C19,'原始数据'!$B$2:$B$3689,0))} -> 4820892 | G19: {=INDEX('原始数据'!F$2:F$3689,MATCH($C19,'原始数据'!$B$2:$B$3689,0))} -> 1106643 | H19: {=INDEX('原始数据'!G$2:G$3689,MATCH($C19,'原始数据'!$B$2:$B$3689,0))} -> 1605421 | I19: {=INDEX('原始数据'!H$2:H$3689,MATCH($C19,'原始数据'!$B$2:$B$3689,0))} -> 1356032 | J19: =IF(F19=0,I19*2,F19/$N$603+I19) -> 2222056.2 | K19: =ROW(K19)-1 -> 18 | L19: {=INDEX(TOP3277!#REF!,MATCH(C19,TOP3277!$B$501:$B$3035,0))} -> 24
A20: 263 | B20: 爱奇艺 | C20: iqiyi.com | D20: {=INDEX('原始数据'!C$2:C$3689,MATCH($C20,'原始数据'!$B$2:$B$3689,0))} -> 3648432 | E20: {=INDEX('原始数据'!D$2:D$3689,MATCH($C20,'原始数据'!$B$2:$B$3689,0))} -> 5828016 | F20: {=INDEX('原始数据'!E$2:E$3689,MATCH($C20,'原始数据'!$B$2:$B$3689,0))} -> 4738224 | G20: {=INDEX('原始数据'!F$2:F$3689,MATCH($C20,'原始数据'!$B$2:$B$3689,0))} -> 1117228 | H20: {=INDEX('原始数据'!G$2:G$3689,MATCH($C20,'原始数据'!$B$2:$B$3689,0))} -> 1588080 | I20: {=INDEX('原始数据'!H$2:H$3689,MATCH($C20,'原始数据'!$B$2:$B$3689,0))} -> 1352654 | J20: =IF(F20=0,I20*2,F20/$N$603+I20) -> 2203827.7 | K20: =ROW(K20)-1 -> 19 | L20: {=INDEX(TOP3277!#REF!,MATCH(C20,TOP3277!$B$501:$B$3035,0))} -> 25
A21: 27 | B21: 中关村在线 | C21: zol.com.cn | D21: {=INDEX('原始数据'!C$2:C$3689,MATCH($C21,'原始数据'!$B$2:$B$3689,0))} -> 2439370 | E21: {=INDEX('原始数据'!D$2:D$3689,MATCH($C21,'原始数据'!$B$2:$B$3689,0))} -> 3896658 | F21: {=INDEX('原始数据'!E$2:E$3689,MATCH($C21,'原始数据'!$B$2:$B$3689,0))} -> 3168014 | G21: {=INDEX('原始数据'!F$2:F$3689,MATCH($C21,'原始数据'!$B$2:$B$3689,0))} -> 1197520 | H21: {=INDEX('原始数据'!G$2:G$3689,MATCH($C21,'原始数据'!$B$2:$B$3689,0))} -> 1741906 | I21: {=INDEX('原始数据'!H$2:H$3689,MATCH($C21,'原始数据'!$B$2:$B$3689,0))} -> 1469713 | J21: =IF(F21=0,I21*2,F21/$N$603+I21) -> 2038814.5 | K21: =ROW(K21)-1 -> 20 | L21: {=INDEX(TOP3277!#REF!,MATCH(C21,TOP3277!$B$501:$B$3035,0))} -> 28
A22: 334 | B22: 百度经验 | C22: jingyan.baidu.com | F22: =SUM(D22+E22)/2 -> 0 | G22: 818986 | H22: 1058383 | I22: =SUM(G22+H22)/2 -> 938684.5 | J22: =IF(F22=0,I22*2,F22/$N$603+I22) -> 1877369 | K22: =ROW(K22)-1 -> 21 | L22: {=INDEX(TOP3277!#REF!,MATCH(C22,TOP3277!$B$501:$B$3035,0))} -> #N/A
A23: 45 | B23: CSDN社区 | C23: csdn.net | D23: {=INDEX('原始数据'!C$2:C$3689,MATCH($C23,'原始数据'!$B$2:$B$3689,0))} -> 4039682 | E23: {=INDEX('原始数据'!D$2:D$3689,MATCH($C23,'原始数据'!$B$2:$B$3689,0))} -> 6452998 | F23: {=INDEX('原始数据'!E$2:E$3689,MATCH($C23,'原始数据'!$B$2:$B$3689,0))} -> 5246340 | G23: {=INDEX('原始数据'!F$2:F$3689,MATCH($C23,'原始数据'!$B$2:$B$3689,0))} -> 672050 | H23: {=INDEX('原始数据'!G$2:G$3689,MATCH($C23,'原始数据'!$B$2:$B$3689,0))} -> 1008281 | I23: {=INDEX('原始数据'!H$2:H$3689,MATCH($C23,'原始数据'!$B$2:$B$3689,0))} -> 840165.5 | J23: =IF(F23=0,I23*2,F23/$N$603+I23) -> 1782617.1 | K23: =ROW(K23)-1 -> 22 | L23: {=INDEX(TOP3277!#REF!,MATCH(C23,TOP3277!$B$501:$B$3035,0))} -> 29
A24: 262 | B24: 京东商城 | C24: jd.com | D24: {=INDEX('原始数据'!C$2:C$3689,MATCH($C24,'原始数据'!$B$2:$B$3689,0))} -> 2490481 | E24: {=INDEX('原始数据'!D$2:D$3689,MATCH($C24,'原始数据'!$B$2:$B$3689,0))} -> 3978298 | F24: {=INDEX('原始数据'!E$2:E$3689,MATCH($C24,'原始数据'!$B$2:$B$3689,0))} -> 3234389.5 | G24: {=INDEX('原始数据'!F$2:F$3689,MATCH($C24,'原始数据'!$B$2:$B$3689,0))} -> 474227 | H24: {=INDEX('原始数据'!G$2:G$3689,MATCH($C24,'原始数据'!$B$2:$B$3689,0))} -> 693151 | I24: {=INDEX('原始数据'!H$2:H$3689,MATCH($C24,'原始数据'!$B$2:$B$3689,0))} -> 583689 | J24: =IF(F24=0,I24*2,F24/$N$603+I24) -> 1164714.1 | K24: =ROW(K24)-1 -> 23 | L24: {=INDEX(TOP3277!#REF!,MATCH(C24,TOP3277!$B$501:$B$3035,0))} -> 47
A25: 56 | B25: 太平洋电脑网 | C25: pconline.com.cn | D25: {=INDEX('原始数据'!C$2:C$3689,MATCH($C25,'原始数据'!$B$2:$B$3689,0))} -> 1270511 | E25: {=INDEX('原始数据'!D$2:D$3689,MATCH($C25,'原始数据'!$B$2:$B$3689,0))} -> 2029517 | F25: {=INDEX('原始数据'!E$2:E$3689,MATCH($C25,'原始数据'!$B$2:$B$3689,0))} -> 1650014 | G25: {=INDEX('原始数据'!F$2:F$3689,MATCH($C25,'原始数据'!$B$2:$B$3689,0))} -> 542177 | H25: {=INDEX('原始数据'!G$2:G$3689,MATCH($C25,'原始数据'!$B$2:$B$3689,0))} -> 765275 | I25: {=INDEX('原始数据'!H$2:H$3689,MATCH($C25,'原始数据'!$B$2:$B$3689,0))} -> 653726 | J25: =IF(F25=0,I25*2,F25/$N$603+I25) -> 950134.22 | K25: =ROW(K25)-1 -> 24 | L25: {=INDEX(TOP3277!#REF!,MATCH(C25,TOP3277!$B$501:$B$3035,0))} -> 60
A26: 177 | B26: 360安全中心 | C26: 360.cn | D26: {=INDEX('原始数据'!C$2:C$3689,MATCH($C26,'原始数据'!$B$2:$B$3689,0))} -> 3190060 | E26: {=INDEX('原始数据'!D$2:D$3689,MATCH($C26,'原始数据'!$B$2:$B$3689,0))} -> 5095812 | F26: {=INDEX('原始数据'!E$2:E$3689,MATCH($C26,'原始数据'!$B$2:$B$3689,0))} -> 4142936 | G26: {=INDEX('原始数据'!F$2:F$3689,MATCH($C26,'原始数据'!$B$2:$B$3689,0))} -> 158977 | H26: {=INDEX('原始数据'!G$2:G$3689,MATCH($C26,'原始数据'!$B$2:$B$3689,0))} -> 224514 | I26: {=INDEX('原始数据'!H$2:H$3689,MATCH($C26,'原始数据'!$B$2:$B$3689,0))} -> 191745.5 | J26: =IF(F26=0,I26*2,F26/$N$603+I26) -> 935981.77 | K26: =ROW(K26)-1 -> 25 | L26: {=INDEX(TOP3277!#REF!,MATCH(C26,TOP3277!$B$501:$B$3035,0))} -> 59
A27: 269 | B27: 腾讯视频 | C27: v.qq.com | D27: {=INDEX('原始数据'!C$2:C$3689,MATCH($C27,'原始数据'!$B$2:$B$3689,0))} -> 1506113 | E27: {=INDEX('原始数据'!D$2:D$3689,MATCH($C27,'原始数据'!$B$2:$B$3689,0))} -> 2405869 | F27: {=INDEX('原始数据'!E$2:E$3689,MATCH($C27,'原始数据'!$B$2:$B$3689,0))} -> 1955991 | G27: {=INDEX('原始数据'!F$2:F$3689,MATCH($C27,'原始数据'!$B$2:$B$3689,0))} -> 244241 | H27: {=INDEX('原始数据'!G$2:G$3689,MATCH($C27,'原始数据'!$B$2:$B$3689,0))} -> 326689 | I27: {=INDEX('原始数据'!H$2:H$3689,MATCH($C27,'原始数据'!$B$2:$B$3689,0))} -> 285465 | J27: =IF(F27=0,I27*2,F27/$N$603+I27) -> 636838.87 | K27: =ROW(K27)-1 -> 26 | L27: {=INDEX(TOP3277!#REF!,MATCH(C27,TOP3277!$B$501:$B$3035,0))} -> 79
A28: 266 | B28: 站长之家 | C28: chinaz.com | D28: {=INDEX('原始数据'!C$2:C$3689,MATCH($C28,'原始数据'!$B$2:$B$3689,0))} -> 1099934 | E28: {=INDEX('原始数据'!D$2:D$3689,MATCH($C28,'原始数据'!$B$2:$B$3689,0))} -> 1757040 | F28: {=INDEX('原始数据'!E$2:E$3689,MATCH($C28,'原始数据'!$B$2:$B$3689,0))} -> 1428487 | G28: {=INDEX('原始数据'!F$2:F$3689,MATCH($C28,'原始数据'!$B$2:$B$3689,0))} -> 313834 | H28: {=INDEX('原始数据'!G$2:G$3689,MATCH($C28,'原始数据'!$B$2:$B$3689,0))} -> 422381 | I28: {=INDEX('原始数据'!H$2:H$3689,MATCH($C28,'原始数据'!$B$2:$B$3689,0))} -> 368107.5 | J28: =IF(F28=0,I28*2,F28/$N$603+I28) -> 624720.65 | K28: =ROW(K28)-1 -> 27 | L28: {=INDEX(TOP3277!#REF!,MATCH(C28,TOP3277!$B$501:$B$3035,0))} -> 91
A29: 332 | B29: 脚本之家 | C29: jb51.net | D29: {=INDEX('原始数据'!C$2:C$3689,MATCH($C29,'原始数据'!$B$2:$B$3689,0))} -> 785075 | E29: {=INDEX('原始数据'!D$2:D$3689,MATCH($C29,'原始数据'!$B$2:$B$3689,0))} -> 1254083 | F29: {=INDEX('原始数据'!E$2:E$3689,MATCH($C29,'原始数据'!$B$2:$B$3689,0))} -> 1019579 | G29: {=INDEX('原始数据'!F$2:F$3689,MATCH($C29,'原始数据'!$B$2:$B$3689,0))} -> 266015 | H29: {=INDEX('原始数据'!G$2:G$3689,MATCH($C29,'原始数据'!$B$2:$B$3689,0))} -> 415010 | I29: {=INDEX('原始数据'!H$2:H$3689,MATCH($C29,'原始数据'!$B$2:$B$3689,0))} -> 340512.5 | J29: =IF(F29=0,I29*2,F29/$N$603+I29) -> 523669.49 | K29: =ROW(K29)-1 -> 28 | L29: {=INDEX(TOP3277!#REF!,MATCH(C29,TOP3277!$B$501:$B$3035,0))} -> 104
A30: 352 | B30: 百度音乐 | C30: music.baidu.com | F30: =SUM(D30+E30)/2 -> 0 | G30: 195025 | H30: 257305 | I30: =SUM(G30+H30)/2 -> 226165 | J30: =IF(F30=0,I30*2,F30/$N$603+I30) -> 452330 | K30: =ROW(K30)-1 -> 29 | L30: {=INDEX(TOP3277!#REF!,MATCH(C30,TOP3277!$B$501:$B$3035,0))} -> #N/A
A31: 265 | B31: IP地址查询 | C31: ip138.com | D31: 1319047 | E31: 2107051 | F31: =SUM(D31+E31)/2 -> 1713049 | G31: 80532 | H31: 135094 | I31: =SUM(G31+H31)/2 -> 107813 | J31: =IF(F31=0,I31*2,F31/$N$603+I31) -> 415544.81 | K31: =ROW(K31)-1 -> 30 | L31: {=INDEX(TOP3277!#REF!,MATCH(C31,TOP3277!$B$501:$B$3035,0))} -> 229
A32: 324 | B32: 多多软件站 | C32: ddooo.com | D32: {=INDEX('原始数据'!C$2:C$3689,MATCH($C32,'原始数据'!$B$2:$B$3689,0))} -> 0 | E32: {=INDEX('原始数据'!D$2:D$3689,MATCH($C32,'原始数据'!$B$2:$B$3689,0))} -> 0 | F32: {=INDEX('原始数据'!E$2:E$3689,MATCH($C32,'原始数据'!$B$2:$B$3689,0))} -> 0 | G32: {=INDEX('原始数据'!F$2:F$3689,MATCH($C32,'原始数据'!$B$2:$B$3689,0))} -> 134333 | H32: {=INDEX('原始数据'!G$2:G$3689,MATCH($C32,'原始数据'!$B$2:$B$3689,0))} -> 252167 | I32: {=INDEX('原始数据'!H$2:H$3689,MATCH($C32,'原始数据'!$B$2:$B$3689,0))} -> 193250 | J32: =IF(F32=0,I32*2,F32/$N$603+I32) -> 386500 | K32: =ROW(K32)-1 -> 31 | L32: {=INDEX(TOP3277!#REF!,MATCH(C32,TOP3277!$B$501:$B$3035,0))} -> 142
A33: 187 | B33: 觅知素材网 | C33: 51miz.com | D33: {=INDEX('原始数据'!C$2:C$3689,MATCH($C33,'原始数据'!$B$2:$B$3689,0))} -> 824261 | E33: {=INDEX('原始数据'!D$2:D$3689,MATCH($C33,'原始数据'!$B$2:$B$3689,0))} -> 1316673 | F33: {=INDEX('原始数据'!E$2:E$3689,MATCH($C33,'原始数据'!$B$2:$B$3689,0))} -> 1070467 | G33: {=INDEX('原始数据'!F$2:F$3689,MATCH($C33,'原始数据'!$B$2:$B$3689,0))} -> 155751 | H33: {=INDEX('原始数据'!G$2:G$3689,MATCH($C33,'原始数据'!$B$2:$B$3689,0))} -> 224229 | I33: {=INDEX('原始数据'!H$2:H$3689,MATCH($C33,'原始数据'!$B$2:$B$3689,0))} -> 189990 | J33: =IF(F33=0,I33*2,F33/$N$603+I33) -> 382288.5 | K33: =ROW(K33)-1 -> 32 | L33: {=INDEX(TOP3277!#REF!,MATCH(C33,TOP3277!$B$501:$B$3035,0))} -> 133
A34: 270 | B34: 华为 | C34: huawei.com | D34: {=INDEX('原始数据'!C$2:C$3689,MATCH($C34,'原始数据'!$B$2:$B$3689,0))} -> 659045 | E34: {=INDEX('原始数据'!D$2:D$3689,MATCH($C34,'原始数据'!$B$2:$B$3689,0))} -> 1052763 | F34: {=INDEX('原始数据'!E$2:E$3689,MATCH($C34,'原始数据'!$B$2:$B$3689,0))} -> 855904 | G34: {=INDEX('原始数据'!F$2:F$3689,MATCH($C34,'原始数据'!$B$2:$B$3689,0))} -> 161946 | H34: {=INDEX('原始数据'!G$2:G$3689,MATCH($C34,'原始数据'!$B$2:$B$3689,0))} -> 217036 | I34: {=INDEX('原始数据'!H$2:H$3689,MATCH($C34,'原始数据'!$B$2:$B$3689,0))} -> 189491 | J34: =IF(F34=0,I34*2,F34/$N$603+I34) -> 343245.44 | K34: =ROW(K34)-1 -> 33 | L34: {=INDEX(TOP3277!#REF!,MATCH(C34,TOP3277!$B$501:$B$3035,0))} -> 147
A35: 203 | B35: 博客园 | C35: cnblogs.com | D35: {=INDEX('原始数据'!C$2:C$3689,MATCH($C35,'原始数据'!$B$2:$B$3689,0))} -> 659174 | E35: {=INDEX('原始数据'!D$2:D$3689,MATCH($C35,'原始数据'!$B$2:$B$3689,0))} -> 1052964 | F35: {=INDEX('原始数据'!E$2:E$3689,MATCH($C35,'原始数据'!$B$2:$B$3689,0))} -> 856069 | G35: {=INDEX('原始数据'!F$2:F$3689,MATCH($C35,'原始数据'!$B$2:$B$3689,0))} -> 160533 | H35: {=INDEX('原始数据'!G$2:G$3689,MATCH($C35,'原始数据'!$B$2:$B$3689,0))} -> 204778 | I35: {=INDEX('原始数据'!H$2:H$3689,MATCH($C35,'原始数据'!$B$2:$B$3689,0))} -> 182655.5 | J35: =IF(F35=0,I35*2,F35/$N$603+I35) -> 336439.58 | K35: =ROW(K35)-1 -> 34 | L35: {=INDEX(TOP3277!#REF!,MATCH(C35,TOP3277!$B$501:$B$3035,0))} -> 149
A36: 191 | B36: 天极网 | C36: yesky.com | D36: {=INDEX('原始数据'!C$2:C$3689,MATCH($C36,'原始数据'!$B$2:$B$3689,0))} -> 415205 | E36: {=INDEX('原始数据'!D$2:D$3689,MATCH($C36,'原始数据'!$B$2:$B$3689,0))} -> 663251 | F36: {=INDEX('原始数据'!E$2:E$3689,MATCH($C36,'原始数据'!$B$2:$B$3689,0))} -> 539228 | G36: {=INDEX('原始数据'!F$2:F$3689,MATCH($C36,'原始数据'!$B$2:$B$3689,0))} -> 139294 | H36: {=INDEX('原始数据'!G$2:G$3689,MATCH($C36,'原始数据'!$B$2:$B$3689,0))} -> 201917 | I36: {=INDEX('原始数据'!H$2:H$3689,MATCH($C36,'原始数据'!$B$2:$B$3689,0))} -> 170605.5 | J36: =IF(F36=0,I36*2,F36/$N$603+I36) -> 267472.32 | K36: =ROW(K36)-1 -> 35 | L36: {=INDEX(TOP3277!#REF!,MATCH(C36,TOP3277!$B$501:$B$3035,0))} -> 180
A37: 413 | B37: 当易网 | C37: downyi.com | D37: {=INDEX('原始数据'!C$2:C$3689,MATCH($C37,'原始数据'!$B$2:$B$3689,0))} -> 310438 | E37: {=INDEX('原始数据'!D$2:D$3689,MATCH($C37,'原始数据'!$B$2:$B$3689,0))} -> 495896 | F37: {=INDEX('原始数据'!E$2:E$3689,MATCH($C37,'原始数据'!$B$2:$B$3689,0))} -> 403167 | G37: {=INDEX('原始数据'!F$2:F$3689,MATCH($C37,'原始数据'!$B$2:$B$3689,0))} -> 137714 | H37: {=INDEX('原始数据'!G$2:G$3689,MATCH($C37,'原始数据'!$B$2:$B$3689,0))} -> 202143 | I37: {=INDEX('原始数据'!H$2:H$3689,MATCH($C37,'原始数据'!$B$2:$B$3689,0))} -> 169928.5 | J37: =IF(F37=0,I37*2,F37/$N$603+I37) -> 242353.35 | K37: =ROW(K37)-1 -> 36 | L37: {=INDEX(TOP3277!#REF!,MATCH(C37,TOP3277!$B$501:$B$3035,0))} -> 194
A38: 339 | B38: php中文网 | C38: php.cn | D38: {=INDEX('原始数据'!C$2:C$3689,MATCH($C38,'原始数据'!$B$2:$B$3689,0))} -> 502376 | E38: {=INDEX('原始数据'!D$2:D$3689,MATCH($C38,'原始数据'!$B$2:$B$3689,0))} -> 802496 | F38: {=INDEX('原始数据'!E$2:E$3689,MATCH($C38,'原始数据'!$B$2:$B$3689,0))} -> 652436 | G38: {=INDEX('原始数据'!F$2:F$3689,MATCH($C38,'原始数据'!$B$2:$B$3689,0))} -> 73012 | H38: {=INDEX('原始数据'!G$2:G$3689,MATCH($C38,'原始数据'!$B$2:$B$3689,0))} -> 104658 | I38: {=INDEX('原始数据'!H$2:H$3689,MATCH($C38,'原始数据'!$B$2:$B$3689,0))} -> 88835 | J38: =IF(F38=0,I38*2,F38/$N$603+I38) -> 206038.48 | K38: =ROW(K38)-1 -> 37 | L38: {=INDEX(TOP3277!#REF!,MATCH(C38,TOP3277!$B$501:$B$3035,0))} -> 214
A39: 1267 | B39: 吾爱破解论 | C39: 52pojie.cn | D39: {=INDEX('原始数据'!C$2:C$3689,MATCH($C39,'原始数据'!$B$2:$B$3689,0))} -> 816360 | E39: {=INDEX('原始数据'!D$2:D$3689,MATCH($C39,'原始数据'!$B$2:$B$3689,0))} -> 1304054 | F39: {=INDEX('原始数据'!E$2:E$3689,MATCH($C39,'原始数据'!$B$2:$B$3689,0))} -> 1060207 | G39: {=INDEX('原始数据'!F$2:F$3689,MATCH($C39,'原始数据'!$B$2:$B$3689,0))} -> 8607 | H39: {=INDEX('原始数据'!G$2:G$3689,MATCH($C39,'原始数据'!$B$2:$B$3689,0))} -> 13770 | I39: {=INDEX('原始数据'!H$2:H$3689,MATCH($C39,'原始数据'!$B$2:$B$3689,0))} -> 11188.5 | J39: =IF(F39=0,I39*2,F39/$N$603+I39) -> 201643.89 | K39: =ROW(K39)-1 -> 38 | L39: {=INDEX(TOP3277!#REF!,MATCH(C39,TOP3277!$B$501:$B$3035,0))} -> 203
A40: 274 | B40: IT猫扑网 | C40: itmop.com | D40: {=INDEX('原始数据'!C$2:C$3689,MATCH($C40,'原始数据'!$B$2:$B$3689,0))} -> 179190 | E40: {=INDEX('原始数据'!D$2:D$3689,MATCH($C40,'原始数据'!$B$2:$B$3689,0))} -> 286238 | F40: {=INDEX('原始数据'!E$2:E$3689,MATCH($C40,'原始数据'!$B$2:$B$3689,0))} -> 232714 | G40: {=INDEX('原始数据'!F$2:F$3689,MATCH($C40,'原始数据'!$B$2:$B$3689,0))} -> 123588 | H40: {=INDEX('原始数据'!G$2:G$3689,MATCH($C40,'原始数据'!$B$2:$B$3689,0))} -> 187468 | I40: {=INDEX('原始数据'!H$2:H$3689,MATCH($C40,'原始数据'!$B$2:$B$3689,0))} -> 155528 | J40: =IF(F40=0,I40*2,F40/$N$603+I40) -> 197332.7 | K40: =ROW(K40)-1 -> 39 | L40: {=INDEX(TOP3277!#REF!,MATCH(C40,TOP3277!$B$501:$B$3035,0))} -> 225
...

Sheet TOP3277访问性+筛查
